Workbook

Sheet 客户精简清单
A1: 优先级 | B1: 企业名称 | C1: 所在省 | D1: 公司营收情况 | E1: 热仿真业务占公司整体业务比重 | F1: 热仿真业务核心产品 | G1: 企业资质 | H1: 企业规模 | I1: 企业关键上下游或关键合作方 | J1: 备注-优先级判断依据
A2: 最高优 | B2: 北京市九州风神科技股份有限公司（DEEPCOOL） | C2: 北京市 海淀区 | D2: 2025年营收10.53亿元 | E2: 高（散热器/热管理为主营业务） | F2: 电子板卡散热 （CPU/服务器散热器、热管模组、电力电子散热） | G2: 专精特新小巨人+新三板 | H2: 员工960人 | I2: 为LED/电力电子/服务器客户提供散热方案；研发体系完善，清华合作研发 | J2: 车灯/散热器是公司核心主业（占比高），体量大、经营状况好，且尚未上AI手段；AI状态：传统CFD仿真
A3: 最高优 | B3: 华域视觉科技（上海）有限公司 | C3: 上海市 嘉定区 | D3: 2025年营收112.69亿元，员工6000+，研发团队500-600人 | E3: 高（车灯/散热业务为主营业务） | F3: 汽车车灯散热（LED车灯散热组件、车载PCB散热） | G3: 大型国企（华域汽车旗下） | H3: 2025年营收112.69亿元，员工6000+，研发团队500-600人 | I3: 上汽集团/华域汽车全资子公司；华域汽车全资子公司，原上海小糸。按弗若斯特沙利文2025年数据，华域视觉中国汽车照明市占率6.8%（81.4亿，国内第二，次于星宇11.6%）、全球3.0%（第九） | J3: 车灯/散热器是公司核心主业（占比高），体量大、经营状况好，且尚未上AI手段；AI状态：传统CAE，公开信息显示正在评估AI方案
A4: 最高优 | B4: 奇宏光电（武汉）有限公司（AVC奇鋐集团） | C4: 湖北省 武汉市 | D4: 母公司奇鋐科技（3017.TW）2025年合并营收1396.39亿新台币（+94.59%）、税后净利191.86亿新台币（+134.78%）；武汉厂单体财报未公开披露 | E4: 高（散热器/热管理为主营业务） | F4: 电子板卡散热（散热器/散热片/导热管/VC/笔记本散热模组） | G4: 瞪羚企业 | H4: 武汉基地员工1940人（2025） | I4: 客户IBM/戴尔/Intel/AMD/华为/联想等 | J4: 车灯/散热器是公司核心主业（占比高），体量大、经营状况好，且尚未上AI手段；AI状态：传统仿真，集团有完整散热与机构模拟软件
A5: 最高优 | B5: 常州星宇车灯股份有限公司 | C5: 江苏省 常州市 | D5: 2025年营收152.57亿元、净利16.24亿元 | E5: 高（车灯/散热业务为主营业务） | F5: 汽车车灯散热（LED车灯总成+铝合金散热结构件） | G5: A股上市 | H5: 员工7532人 | I5: 国内车灯龙头，招股书口径2025年中国汽车照明市占率11.6%（国内第一）、全球4.6%（第七），智能车灯中国28.4%（第一）。核心目标客户 | J5: 车灯/散热器是公司核心主业（占比高），体量大、经营状况好，且尚未上AI手段，AI状态：传统Ansys/Icepak仿真
A6: 最高优 | B6: 浙江嘉利（丽水）工业股份有限公司 | C6: 浙江省 丽水市 | D6: 2025年营收30.41亿元 | E6: 高（车灯/散热业务为主营业务） | F6: 汽车车灯散热+车载电子板卡散热（车灯散热铝构件、车载电子板卡散热件） | G6: 新三板挂牌+高新 | H6: 员工4820人 | I6: 新三板挂牌，横店集团得邦照明（603303）控股；1000-4999人规模，20年历史，车灯整车配套 | J6: 车灯/散热器是公司核心主业（占比高），体量大、经营状况好，且尚未上AI手段；AI状态：CAE仿真覆盖光学、视觉、热学、雾气、力学、模流——已有专职热
A7: 最高优 | B7: 迅驰车业江苏有限公司 | C7: 江苏省 镇江市 | D7: 2025年营收10.88亿元（全年产值预计15亿） | E7: 高（车灯/散热业务为主营业务） | F7: 汽车车灯散热（LED车灯铝制散热器、光学散热组件） | G7: 高新+专精特新 | H7: 员工359人（参保）+约百人自研团队 | I7: 客户含上汽、蔚来、奇瑞、比亚迪、小米 | J7: 车灯/散热器是公司核心主业（占比高），体量大、经营状况好，且尚未上AI手段；AI状态：传统CAE
A8: 最高优 | B8: 金业车灯控股集团（浙江金业汽车部件） | C8: 浙江省 宁波市 | D8: 未公开披露财报；2023-2024年产值均约30亿元、年出口约3亿元，非上市 | E8: 高（车灯/散热业务为主营业务） | F8: 汽车车灯散热（前照灯/后尾灯总成、车灯电子、模具） | G8: 国家高新技术企业 | H8: 员工3000-4300人 | I8: 吉利最大车灯供应商，配套Volvo/Smart/路特斯/长城/大众；5000-9999人规模，大型车灯配套企业，宁波杭州湾新区 | J8: 车灯/散热器是公司核心主业（占比高），体量大、经营状况好，且尚未上AI手段；AI状态：传统CAE
A9: 优 | B9: 杭州微焓科技有限公司（曾用名：北京微焓科技有限公司 | C9: 北京市 海淀区 | D9: 未公开集团合并财报；注册资本 1000 万元；子公司山东微焓 2024 年前 9 月销售额 4000 万元（地方产业调研口径，无审计财报） | E9: 高（热仿真/热分析本身就是其核心交付内容） | F9: 电子板卡散热 + 热控服务（液冷板、均温板、环路热管、高导热材料；6U板卡散热设计、单板/组件/系统级热分析与热试验） | G9: 国家级高新+省级专精特新 | H9: 早期调研口径 21–50 人；集团（含各子公司）2025 年合计参保约 177 人，人员分散在多地子公司 | I9: 中国第一家民营商业航天热控系统供应商，热控方案已应用于超300颗卫星及深空探测器；中国第一家民营商业航天热控系统供应商，海淀丰秀中路 | J9: 产品场景与FEMAI车灯/板卡散热直接匹配，未上AI；体量或盈利待拜访核实，付费能力为关键变量；AI状态：传统热分析仿真
A10: 优 | B10: 嘀视科技（杭州）有限公司 | C10: 浙江省 杭州市临安区 | D10: 未公开披露财报；注册资本1250万元（实缴1167万）、2022年A轮；临安新基地规划年产值8亿元 | E10: 高（车灯/散热业务为主营业务） | F10: 汽车车灯散热+车载电子板卡散热（智能LED车灯总成、光学透镜及散热件、车载PCB散热件） | G10: 高新+专精特新 | H10: 员工263人 | I10: 核心客户含本田、比亚迪、雅迪、九号、小米，以两轮/短途出行照明为主 | J10: 产品场景与FEMAI车灯/板卡散热直接匹配，未上AI；体量或盈利待拜访核实，付费能力为关键变量；AI状态：传统CAE
A11: 优 | B11: 广州高澜节能技术股份有限公司 | C11: 广东省 广州市 | D11: 2025年营收9.89亿元（+43.09%）、归母净利2838万元（+156.40%），员工811人（2025年） | E11: 中（热管理为主营，热仿真用于冷板/CDU/阀冷系统设计选型，属核心研发手段但无独立收入；非车灯/板卡结构件场景） | F11: 算力/电力电子液冷（数据中心液冷、高功率密度装置热管理、电力电子纯水冷却设备）——属系统级温控而非车灯/板卡散热结构件 | G11: 国家级专精特新小巨人+国家技术创新示范企业+国家制造业单项冠军示范企业 | H11: 2025年营收9.89亿元（+43.09%）、归母净利2838万元（+156.40%），员工811人（2025年） | I11: 客户含国网、南网、宁德时代、字节跳动、阿里巴巴、腾讯；"英伟达核心液冷供应商"未找到官方口径佐证，拜访时应当面确认；公开信息仅显示CNAS认可的"热物理仿真实验室""工控仿真实验室"，属传统仿真。已改为待核实。【重要】原备注"偏电力工业冷却"已过时——高澜已是数据中心液冷头部厂商（创业板300499… | J11: 热管理为核心业务、盈利高增长（2025净利+156%），但主业为系统级液冷温控而非车灯/板卡散热结构件，场景匹配度打折；AI使用状态需重点求证：公开未见AI仿真证据
A12: 优 | B12: 成都东浩散热器有限公司 | C12: 四川省 成都市 | D12: 未公开披露财报；注册资本1200万元、2025年参保94人，成都+德阳两基地 | E12: 高（散热器/热管理为主营业务） | F12: 电子板卡散热（电力半导体器件用散热器、工业散热器、水冷板、充电桩散热；铝型材散热器规格超2000种） | G12: 高新+专精特新 | H12: 2025年参保94人（2024年约108人） | I12: 客户覆盖省级制造业单项冠军企业 | J12: 产品场景与FEMAI车灯/板卡散热直接匹配，未上AI；体量或盈利待拜访核实，付费能力为关键变量；AI状态：传统仿真
... A56: 低级 | B56: 青岛汽车散热器有限公司 | C56: 山东省 青岛市 | D56: 未公开披露；注册资本3373万元实缴、2025年参保90人、划型小型企业 | E56: 低（主营为发动机/整车/采暖/电力等散热，非车灯、板卡散热结构） | F56: 非目标场景：汽车散热器、汽车空调冷凝器 | G56: 高新+专精特新 | H56: 2025年员工90人（官网口径180人） | I56: 母公司青岛海星热控科技；配套宇通客车、中国重汽、潍柴动力、康明斯；中标中石油济柴散热器采购 | J56: 主营业务不在FEMAI两大场景（车灯散热/板卡散热）内，按筛选漏斗淘汰至低级；AI状态：传统CFD
A57: 待定 | B57: 东风马勒热系统有限公司 | C57: 湖北省 武汉市 | D57: 未上市无财报；重组文件披露主营收入2023年13.88亿→2025年14.88亿元；企查查2025年营收11.85亿元；净利未披露 | E57: 中（仿真嵌入空调/发动机冷却两大产品线开发—样件—试验体系，属内部研发环节，无独立收入） | F57: 汽车热系统（散热器、冷凝器、蒸发器、空调总成）——整车热系统，非车灯/板卡散热 | G57: 高新+制造业单项冠军 | H57: 2025年参保282人（企查查）；公司自述武汉/十堰/成都/广州四基地员工逾千人 | I57: 股东为东风电子科技（600081）与德国MAHLE各50%；客户含东风商用车（占收入约20%）、东风日产、神龙、陕汽、广汽本田、潍柴
A58: 待定 | B58: 深圳市英维克科技股份有限公司 | C58: 广东省 深圳市 | D58: 2025年营收60.68亿元（+32.23%）、归母净利5.22亿元（+15.30%）；2024年45.89亿/4.53亿；2023年35.29亿/3.44亿 | E58: 高（散热/热管理为核心业务），但已自研/使用AI仿真 | F58: 算力液冷（数据中心液冷、服务器散热、机柜空调）——属系统级温控，非车灯/板卡散热结构件 | G58: A股上市 | H58: 员工5697人（2025年末年报口径），同比+11.07% | I58: 终端客户含字节跳动、腾讯、阿里巴巴、中国移动、中国电信；为Google定制CDU，UQD进入英伟达GB200/300 RVL | J58: 已自研/使用AI热仿真手段，不符合"还没上AI"的筛选条件；AI使用状态需重点求证

Sheet 联系方式（备用）
A1: 企业名称 | B1: 优先级 | C1: 详细地址 | D1: 总机电话 | E1: 公示手机 | F1: 公开邮箱 | G1: 关键决策人（姓名+职务） | H1: 官网
A2: 北京市九州风神科技股份有限公司（DEEPCOOL） | B2: 最高优 | C2: 北京市海淀区地锦路9号院10号楼1至4层101（中关村环保示范园，北清路156号；邮编100095） | D2: 010-56401820 | F2: ldf@deepcool.com | G2: 夏春秋（董事长兼总经理）；刘欣（董事会秘书）；李德芳（证券事务代表） | H2: www.deepcool.com | I2: =VLOOKUP(A2,客户精简清单!$B:$B,1,0) -> 北京市九州风神科技股份有限公司（DEEPCOOL）
A3: 华域视觉科技（上海）有限公司 | B3: 最高优 | C3: 上海市嘉定区叶城路767号（邮编201821） | D3: 021-67085999 | F3: hv02@hascovision.com | G3: 王卫中（法定代表人、董事长）； 茅海峰（总经理、董事） | H3: www.hascovision.com | I3: =VLOOKUP(A3,客户精简清单!$B:$B,1,0) -> 华域视觉科技（上海）有限公司
A4: 奇宏光电（武汉）有限公司（AVC奇鋐集团） | B4: 最高优 | C4: 湖北省武汉市东湖新技术开发区龙泉大道9号凤凰山产业基地第一期工程S31-A3厂房栋/单元1-4层（一照多址）；另一厂区：武汉市东湖新技术开发区光谷三路777号 | D4: 027-86558899 | F4: jack_meng@avc.com | G4: 陈彦良（法定代表人）;沈庆行（执行董事兼总经理） | H4: https://www.avc.com.tw（集团官网 www.avc.co） | I4: =VLOOKUP(A4,客户精简清单!$B:$B,1,0) -> 奇宏光电（武汉）有限公司（AVC奇鋐集团）
A5: 常州星宇车灯股份有限公司 | B5: 最高优 | C5: 江苏省常州市新北区秦岭路182号（办公地址，邮编213022）；注册地址：常州市新北区汉江路398号 | D5: 0519-85156063 | F5: xingyu@xyl.cn | G5: 周晓萍（法定代表人、董事长）； 高鹏（董事会秘书） | H5: www.xyl.cn | I5: =VLOOKUP(A5,客户精简清单!$B:$B,1,0) -> 常州星宇车灯股份有限公司
A6: 浙江嘉利（丽水）工业股份有限公司 | B6: 最高优 | C6: 浙江省丽水市莲都区水阁工业园区丽沙路1号（南明山街道；丽水经济技术开发区） | D6: 0578-2698080；0578-2698020（丽水公司，官网/行业协会页） | F6: lishuijiali@vip.163.com；hanzhanchu@cnjiali.com（董事会秘书） | G6: 黄光华（董事长、法定代表人，2026-08-28变更）；黄玉琦（总经理、名誉董事长、实际控制人）；韩展初（董事会秘书） | H6: http://www.cnjiali.com | I6: =VLOOKUP(A6,客户精简清单!$B:$B,1,0) -> 浙江嘉利（丽水）工业股份有限公司
A7: 迅驰车业江苏有限公司 | B7: 最高优 | C7: 江苏省镇江市丹阳市丹北镇（新桥）群楼工业园（邮编212322） | D7: 0511-86052292 | F7: xunchi@vip.163.com | G7: 张荣平（法定代表人） | H7: www.xunchilamp.com | I7: =VLOOKUP(A7,客户精简清单!$B:$B,1,0) -> 迅驰车业江苏有限公司
A8: 金业车灯控股集团（浙江金业汽车部件） | B8: 最高优 | C8: 浙江省宁波杭州湾新区滨海五路136号 | D8: 0574-58580375（官网服务热线） | F8: seekin888@seekin.com.cn | G8: 刘宗良（执行董事、经理，持股90%）；刘子豪（监事，持股10%）；王珍璐（总经理） | H8: https://www.seekin.com.cn | I8: =VLOOKUP(A8,客户精简清单!$B:$B,1,0) -> 金业车灯控股集团（浙江金业汽车部件）
A9: 杭州微焓科技有限公司（曾用名：北京微焓科技有限公司 | B9: 优 | C9: 北京市海淀区丰秀中路3号院13号楼5层（501）；江苏地址：江苏省溧阳市溧城镇创智园南区24号 | D9: 010-56377456 | F9: bjwhkj@thermatech.cn | G9: 孙萌（法定代表人）；连红奎（总经理）；张晓屿（微焓研究院院长） | H9: www.thermatech.cn | I9: =VLOOKUP(A9,客户精简清单!$B:$B,1,0) -> 杭州微焓科技有限公司（曾用名：北京微焓科技有限公司
A10: 嘀视科技（杭州）有限公司 | B10: 优 | C10: 浙江省杭州市临安区青山湖街道高庆路108号（另见百科地址：杭州市临安区青山湖街道滨河南路398号1幢整幢） | D10: 0571-88105333 | F10: sitis@sitis.com.cn | G10: 王爽（法定代表人）；王书仓（董事长） | H10: http://www.sitis.com.cn | I10: =VLOOKUP(A10,客户精简清单!$B:$B,1,0) -> 嘀视科技（杭州）有限公司
A11: 广州高澜节能技术股份有限公司 | B11: 优 | C11: 广东省广州市高新技术产业开发区科学城南云五路3号（标准化地址：广州市黄埔区联和街道南云五路3号，邮编510663） | D11: 020-66616248；020-62800188 | F11: ir@goaland.com.cn | G11: 李琦（法定代表人、董事长）；关胜利（总经理、职工代表董事、财务总监）；王杨阳（董事会秘书）；李慕牧（副总经理）；吴玉纯（证券事务代表） | H11: www.goaland.com.cn | I11: =VLOOKUP(A11,客户精简清单!$B:$B,1,0) -> 广州高澜节能技术股份有限公司
A12: 成都东浩散热器有限公司 | B12: 优 | C12: 四川省成都经济技术开发区（龙泉驿区）南一路999号3栋1层1号（工商注册）；通信/厂区地址：成都市龙泉驿区西河镇螺丝路429号；另有德阳生产基地 | D12: 028-84890051 | F12: 1729107222@qq.com | G12: 朱敏（法定代表人/执行董事兼总经理，持股34%）;朱东霞（监事）;朱浩天（股东，持股33%）;朱显成（股东，持股33%） | H12: https://www.cddhsrq.com | I12: =VLOOKUP(A12,客户精简清单!$B:$B,1,0) -> 成都东浩散热器有限公司
A13: 昆山固特杰散热产品有限公司 | B13: 优 | C13: 江苏省苏州市昆山市开发区蓬朗镇八字庙路2号（昆山工厂）；盐城工厂：江苏省盐城市盐都区盐龙街道合心路38号；（工商注册地址：昆山开发区蓬朗大通路南侧、吴泾路东侧） | D13: 0512-57813508 | F13: marketing@gootage.com | G13: 吴斌（法定代表人/董事长/总经理）;沈林（董事/股东）;严福山（董事） | H13: https://www.gootage.com | I13: =VLOOKUP(A13,客户精简清单!$B:$B,1,0) -> 昆山固特杰散热产品有限公司
... A20: 莹帆科技（重庆璧山） | B20: 优 | C20: 重庆市璧山区青杠街道新立路51号1号厂房、2号厂房、3号厂房、4号厂房 | D20: 023-41801688 | F20: liyue@yingfanjm.com | G20: 童小飞（董事长/总经理/法定代表人）;杨端谊（控股股东/实际控制人）;张媛媛（董事会秘书）;周菊香（副总经理）;孙超（副总经理） | H20: http://www.yingfanjm.com | I20: =VLOOKUP(A20,客户精简清单!$B:$B,1,0) -> 莹帆科技（重庆璧山）
A21: 西安隆源热技术有限公司 | B21: 优 | C21: 陕西省西安市临潼区代新工业园内代新路68号 | D21: 029-83888032 | F21: xianlongyuan@188.com | G21: 祁占成（法定代表人，关联企业7家） | I21: =VLOOKUP(A21,客户精简清单!$B:$B,1,0) -> 西安隆源热技术有限公司
A22: 迈泰技术（Walmate） | B22: 优 | C22: 注册地址：广东省东莞市横沥镇红旗路45号（2026-09-21住所变更后）；研发总部：东莞市横沥镇崇德路135号；华南基地：东莞市横沥镇六甲新兴北路1号；华东基地：安徽省蚌埠市燕南路1308号 | D22: 0769-82869092（2025年报披露） | F22: acct1@walmate-cn.com（年报披露）；selena@walmatethermal.com（官网Contact页商务联系人） | G22: 刘加良（法定代表人、董事长、经理，持股37%） | H22: www.walmate.com；walmatethermal.com（英文/外贸站） | I22: =VLOOKUP(A22,客户精简清单!$B:$B,1,0) -> 迈泰技术（Walmate）
A23: 上海浙东铝业股份有限公司 | B23: 中级 | C23: 上海市金山区漕泾镇漕廊公路1559号（邮编201507） | D23: 021-67252960；021-67252950 | F23: zdoon-al@zcone.com.cn | G23: 邱风雷（法定代表人、实际控制人，持股75.18%）；周坤如（总经理）；赵运红（董事会秘书） | H23: www.zdoon-al.com | I23: =VLOOKUP(A23,客户精简清单!$B:$B,1,0) -> 上海浙东铝业股份有限公司
A24: 厦门利德宝电子科技股份有限公司 | B24: 中级 | C24: 福建省厦门市集美区灌口镇山美路662号（厦门工厂）；漳州工厂：漳州台商投资区龙池开发区保生路通用1号厂房 | D24: 0592-7792855 | F24: qxp@xmledpcb.com | G24: 吴志敬（法定代表人/董事长，持股18.75%）;江东红（副董事长）;花戊戍（董事/总经理）;邱新平（副总经理/董事会秘书）;黄小青（财务总监）;杨贤伟（董事）;洪权实（董事） | H24: http://www.xmledpcb.com | I24: =VLOOKUP(A24,客户精简清单!$B:$B,1,0) -> 厦门利德宝电子科技股份有限公司
A25: 市光法雷奥（佛山）汽车照明系统有限公司 | B25: 中级 | C25: 广东省佛山市禅城区佛山国家高新技术产业开发区城西园华宝南路7号（张槎街道） | D25: 0757-88013958（2025年工商年报）；0757-88011178 / 0757-63523765（法雷奥官网站点页） | G25: 张锋（法定代表人、执行公司事务的董事）；周松（董事长）；陈蕾（总经理） | H25: https://www.valeo.com（法雷奥集团官网中国站点列表） | I25: =VLOOKUP(A25,客户精简清单!$B:$B,1,0) -> 市光法雷奥（佛山）汽车照明系统有限公司
A26: 广州小糸车灯有限公司 | B26: 中级 | C26: 广东省广州市番禺区石楼镇岳溪村跨国产业基地B01（邮编511447） | D26: 020-39307015（另见总机020-39307000） | F26: li-jiming@gkoito.com | G26: 内山正巳（法定代表人、董事长） | H26: https://www.koito.co.jp（小糸制作所全球网点页；黄页另列 g-koito.com） | I26: =VLOOKUP(A26,客户精简清单!$B:$B,1,0) -> 广州小糸车灯有限公司
A27: 福建臻璟新材料科技有限公司 | B27: 中级 | C27: 福建省泉州市安溪县龙门镇环城东路1号（安溪2025产业园） | F27: zhanww@zingin.cn（基板事业部）;wengmb@zingin.cn（粉体事业部） | G27: 林桂敏（法定代表人/经理，2024年12月起任职）;LIN WEI YI（董事长）;林淑霞（董事）;戚玉凤（董事）;叶巧艺（财务负责人）;苏文勇（监事） | H27: https://www.zingin.com.cn（集团站另见 zingin.co） | I27: =VLOOKUP(A27,客户精简清单!$B:$B,1,0) -> 福建臻璟新材料科技有限公司
A28: 苏州天脉导热科技股份有限公司 | B28: 中级 | C28: 江苏省苏州市吴中区甪直镇汇凯路68号（邮编215127） | D28: 0512-66028722 | F28: zq@sz-tianmai.com | G28: 谢毅（法定代表人、董事长、总经理）；龚才林（董事、董事会秘书、财务总监）；沈锋华（董事、商务中心总监）；史国昌（职工代表董事、区域销售总监）；丁幸强（副总经理、产品开发部总监）；刘晓阳（副总经理、材料研发部总监）；何亚南（证券事务代表） | H28: www.sz-tianmai.com | I28: =VLOOKUP(A28,客户精简清单!$B:$B,1,0) -> 苏州天脉导热科技股份有限公司
A29: 苏州市华泰精密机械有限公司 | B29: 中级 | C29: 江苏省苏州市相城区黄埭镇春秋路8号（潘阳工业区） | D29: 0512-65713128 | F29: hua_tai@szhtpe.com | G29: 王建平（法定代表人/执行董事兼总经理，持股40%）;沈玮平（监事，持股60%） | H29: https://www.htjm.com.cn（另 szhtpe.com 同为官网域名） | I29: =VLOOKUP(A29,客户精简清单!$B:$B,1,0) -> 苏州市华泰精密机械有限公司
A30: 重庆光大照明科技有限公司 | B30: 中级 | I30: =VLOOKUP(A30,客户精简清单!$B:$B,1,0) -> 重庆光大照明科技有限公司
A31: 韦尔通科技股份有限公司 | B31: 中级 | C31: 福建省厦门市火炬高新区同翔高新城新厝北路1-2号（同安区洪塘镇） | D31: 0592-7163381 | F31: service@weldtone.com | G31: 林鸿腾（法定代表人） | H31: https://www.weldtone.com（品牌站 www.weldbond.com.cn） | I31: =VLOOKUP(A31,客户精简清单!$B:$B,1,0) -> 韦尔通科技股份有限公司
A32: 马瑞利汽车照明系统（佛山）有限公司 | B32: 中级 | C32: 广东省佛山市南海区丹灶镇南海国家生态工业示范园区凤凰大道16号（生产车间1号） | D32: 0757-85130898（2025年工商年报） | G32: KELEI SHEN（法定代表人） | H32: https://themarellihub.marelli.com（马瑞利集团官网 marelli.com） | I32: =VLOOKUP(A32,客户精简清单!$B:$B,1,0) -> 马瑞利汽车照明系统（佛山）有限公司
A33: 友邦散热器（常熟）股份有限公司 | B33: 低级 | C33: 江苏省苏州市常熟市董浜镇华烨大道30号（邮编215534） | D33: 0512-52681425（官网联系我们）；0512-52687651（北交所保荐书/年报披露总机） | F33: info@ybsrq.com（官网）；swong@ybsrq.com（董秘，北交所披露） | G33: 王建忠（法定代表人、董事长、实际控制人）；王晟（董事会秘书、信息披露负责人）；方琴芬（实际控制人） | H33: www.ybsrq.com | I33: =VLOOKUP(A33,客户精简清单!$B:$B,1,0) -> 友邦散热器（常熟）股份有限公司
A34: 圣春散热器有限公司 | B34: 低级 | C34: 河北省衡水市冀州区冀新西路86号（第二经营场所：衡水市冀州区长安路南侧春风街西侧） | D34: 0318-8615653；0318-8613231；0318-8612128 | F34: sales@shengchun.com.cn | G34: 李京环（法定代表人、董事、经理）；崔可忠（监事）；曹宝华（母公司春风实业集团董事局主席兼CEO） | H34: www.shengchun.com.cn | I34: =VLOOKUP(A34,客户精简清单!$B:$B,1,0) -> 圣春散热器有限公司
A35: 奥卡冷却系统（天津）有限公司 | B35: 低级 | C35: 天津市武清区京滨工业园民旺路8号 | D35: 022-22232860 | F35: weiwei.sun@orcacooling.com；lucy.liu@rs-promotion.com.cn | G35: 孙鲲（法定代表人） | I35: =VLOOKUP(A35,客户精简清单!$B:$B,1,0) -> 奥卡冷却系统（天津）有限公司
A36: 威海邦德散热系统股份有限公司 | B36: 低级 | C36: 山东省威海市环翠区桥头镇兴达路5号（桥头医院东） | D36: 0631-5528111 | F36: bd@bdcooling.com；bangde@bdcooling.com | G36: 吴国良（董事长、总经理、法定代表人）；盛红春（董事会秘书、财务负责人） | H36: www.bdcooling.com | I36: =VLOOKUP(A36,客户精简清单!$B:$B,1,0) -> 威海邦德散热系统股份有限公司
A37: 安徽文轩新能源热管理系统有限公司 | B37: 低级 | C37: 安徽省六安市金安区三十铺镇长淮路128号（工商注册地，2024-07-15由“长淮路128号1号厂房”变更；合肥长丰厂区：合肥市长丰县吴山镇百花大道与高岗路交口3号厂房） | D37: 0551-66855607；0551-66861060 | F37: lin.li@winsharethermal.com；jw.lin@winsharethermal.com | G37: 周吉勇（法定代表人、CEO、创始人） | H37: www.winsharethermal.com | I37: =VLOOKUP(A37,客户精简清单!$B:$B,1,0) -> 安徽文轩新能源热管理系统有限公司
A38: 安徽阳德温控科技有限公司 | B38: 低级 | C38: 安徽省六安市舒城县杭埠镇安徽南聚杭埠工业园F区8#厂房 | D38: 0551-62062036 | F38: ellasong@sunmoral.com；dj_finance@sunmoral.com | G38: 宋晶婷（法定代表人） | H38: www.sunmoral.com | I38: =VLOOKUP(A38,客户精简清单!$B:$B,1,0) -> 安徽阳德温控科技有限公司
A39: 山东厚丰汽车散热器有限公司 | B39: 低级 | C39: 山东省泰安市泰山区灵山大街282号（工商注册地，2026-04-29变更为一照多址）；官网联系地址：泰安市擂鼓石大街112号 | D39: 0538-8628618；0538-8628669 | F39: houfngceo@vip.163.com；maryzx@263.net（进出口公司） | G39: 张广厚（董事长、法定代表人兼经理）；刘爱勇（董事）；张兆芳（董事） | H39: www.houfeng.cn | I39: =VLOOKUP(A39,客户精简清单!$B:$B,1,0) -> 山东厚丰汽车散热器有限公司
A40: 廊坊汇钰模塑有限公司（钰顺汽车） | B40: 低级 | C40: 河北省廊坊市安次区仇庄乡（镇）付庄村村口（地图POI另标注为安次区仇庄镇付庄村23号） | D40: 0316-2573006；0316-2573008；0316-2573007 | F40: hengse@vip.sina.com | G40: 陈力恒（法定代表人） | H40: www.lfhuiyu.com | I40: =VLOOKUP(A40,客户精简清单!$B:$B,1,0) -> 廊坊汇钰模塑有限公司（钰顺汽车）
A41: 捷温汽车系统（中国）有限公司 | B41: 低级 | C41: 河北省廊坊经济技术开发区金源道3号（西门位于金源道3号，北门临近万福路与海棠路交叉口西南166米） | D41: 0316-6071100 | F41: marketing.asia@gentherm.com；allen.guo@gentherm.com | G41: 王成龙（法定代表人、董事长兼总经理；捷温集团副总裁、亚洲区总裁兼汽车事业部总经理）；国雷（董事）；Wayne Swoyer Kauffman III（董事） | H41: www.gentherm.com（中文站www.gentherm.cn） | I41: =VLOOKUP(A41,客户精简清单!$B:$B,1,0) -> 捷温汽车系统（中国）有限公司
A42: 新南风加热制冷（沧州）有限公司 | B42: 低级 | C42: 河北省沧州市南皮县乌马营镇西正港路南侧（官网标为南皮县乌马营工业区） | D42: 0317-8619999；0317-8616759（销售） | F42: anne.feng@newnanfeng.com；sunny.liu@newnanfeng.com | G42: 刘志涛（法定代表人）；门政妆（执行董事）；门少杰（经理） | H42: www.newnanfeng.com | I42: =VLOOKUP(A42,客户精简清单!$B:$B,1,0) -> 新南风加热制冷（沧州）有限公司
A43: 江苏嘉和热系统股份有限公司 | B43: 低级 | C43: 江苏省扬州市广陵产业园扬霍路168号（广陵区扬霍路168号，邮编225000） | D43: 0514-85555079（内贸）；0514-85555991（外贸）；0514-85555978（年报披露总机） | F43: hr@cnjiahe.com.cn（年报披露，为人事邮箱，无公开销售邮箱） | G43: 李宝民（董事长）；穆轶（总经理）；毕文平（常务副总经理）；彭文生（董事、副总经理、董事会秘书） | H43: www.cnjiahe.com.cn | I43: =VLOOKUP(A43,客户精简清单!$B:$B,1,0) -> 江苏嘉和热系统股份有限公司
A44: 江苏维创散热器制造有限公司 | B44: 低级 | C44: 江苏省扬州市江都区邵伯镇工业集中区（邵伯工业园区6号路；招聘信息另署新时路8号）；山东工厂：山东省潍坊市安丘市兴安街道翠山街与珠江路路口西 | D44: 0514-80916509；400-180-4088；0514-80916502 | F44: wcradiator@jswcsrq.com；474220267@qq.com | G44: 景庆琳（法定代表人、执行董事）；刘大忠（股东、经理）；刘大志（监事） | H44: www.jswcsrq.com | I44: =VLOOKUP(A44,客户精简清单!$B:$B,1,0) -> 江苏维创散热器制造有限公司
A45: 江苏腾奇电力科技股份有限公司 | B45: 低级 | C45: 江苏省常州市钟楼区新前路56号（新闸街道新前路56号，邮编213000）；浙江基地：浙江省台州市海游街道西区大道413号 | D45: 0519-85866772（总机，2025年报及第三方上市公司资料一致） | F45: caiwenhuan@cztengqi.com；caiwenhuan@wetqt.com（官网联系我们页） | G45: 史正生（董事长、法定代表人、总经理、控股股东）；蔡文欢（董事会秘书） | H45: wetqt.com（品牌升级后新官网）；www.cztengqi.com（原官网） | I45: =VLOOKUP(A45,客户精简清单!$B:$B,1,0) -> 江苏腾奇电力科技股份有限公司
A46: 浙江开山银轮换热器有限公司 | B46: 低级 | C46: 浙江省衢州市柯城区凯旋西路9号5幢1楼（一照多址；分支机构生产场所：衢州市芳桂中路3号） | D46: 0570-3662357；0570-3665287 | G46: 杨建军（董事长、法定代表人）；朱旭（董事、经理）；陈敏（董事）；胡奕忠（董事）；王晶鑫（董事）；许爱萍（监事）；周慧娟（财务负责人） | H46: kaishanyinlun.com | I46: =VLOOKUP(A46,客户精简清单!$B:$B,1,0) -> 浙江开山银轮换热器有限公司
...
